<mujoco model="xarm7_hand">
  <asset>
    <material name="white" rgba="1 1 1 1"/>
    <material name="black" rgba="0.149 0.149 0.149 1"/>

    <mesh name="base_link" file="meshes/xarm7_gripper/base_link.stl"/>
    <mesh name="left_outer_knuckle" file="meshes/xarm7_gripper/left_outer_knuckle.stl"/>
    <mesh name="left_finger" file="meshes/xarm7_gripper/left_finger.stl"/>
    <mesh name="left_inner_knuckle" file="meshes/xarm7_gripper/left_inner_knuckle.stl"/>
    <mesh name="right_outer_knuckle" file="meshes/xarm7_gripper/right_outer_knuckle.stl"/>
    <mesh name="right_finger" file="meshes/xarm7_gripper/right_finger.stl"/>
    <mesh name="right_inner_knuckle" file="meshes/xarm7_gripper/right_inner_knuckle.stl"/>
  </asset>


  <worldbody>
    <body name="xarm_gripper_base_link">
      <inertial pos="-0.00065489 -0.0018497 0.048028" quat="0.997403 -0.0717512 -0.0061836 0.000477479" mass="0.54156"
        diaginertia="0.000471093 0.000332307 0.000254799"/>
      <geom type="mesh" mesh="base_link" material="white" group="1"/>
      <body name="left_outer_knuckle" pos="0 0.035 0.059098">
        <inertial pos="0 0.021559 0.015181" quat="0.47789 0.87842 0 0" mass="0.033618"
          diaginertia="1.9111e-05 1.79089e-05 1.90167e-06"/>
        <joint range="0 0.85" axis="1 0 0" frictionloss="1" name="left_driver_joint" armature="0.005" damping="0.1" solreflimit="0.005 1"/>
        <geom type="mesh" material="black" mesh="left_outer_knuckle" group="1"/>
        <body name="left_finger" pos="0 0.035465 0.042039">
	  <geom size="0.008 0.004 0.008" pos="0 -0.005 -0.015" quat="0 0 0 1" type="box" group="0" solref="0.01 0.5" friction = "2 0.05 0.0001" conaffinity="1" contype="1" name="finger1_pad_collision"/>
          <inertial pos="0 -0.016413 0.029258" quat="0.697634 0.115353 -0.115353 0.697634" mass="0.048304"
            diaginertia="1.88037e-05 1.7493e-05 3.56792e-06"/>
          <joint range="0 0.85" frictionloss="1" name="left_finger_joint" axis="-1 0 0" solreflimit="0.005 1"/>
          <geom type="mesh" material="black" mesh="left_finger" group="1"/>
        </body>
      </body>
      <body name="left_inner_knuckle" pos="0 0.02 0.074098">
        <inertial pos="1.86601e-06 0.0220468 0.0261335" quat="0.664139 -0.242732 0.242713 0.664146" mass="0.0230126"
          diaginertia="8.34216e-06 6.0949e-06 2.75601e-06"/>
        <joint range="0 0.85" axis="1 0 0" frictionloss="1" name="left_inner_knuckle_joint" stiffness="0.05" springref="2.62" damping="0.00125"/>
        <geom type="mesh" material="black" mesh="left_inner_knuckle" group="1"/>
      </body>
      <body name="right_outer_knuckle" pos="0 -0.035 0.059098">
        <inertial pos="0 -0.021559 0.015181" quat="0.87842 0.47789 0 0" mass="0.033618"
          diaginertia="1.9111e-05 1.79089e-05 1.90167e-06"/>
        <joint range="0 0.85" frictionloss="1" name="right_driver_joint" axis="-1 0 0" armature="0.005" damping="0.1" solreflimit="0.005 1"/>
        <geom type="mesh" material="black" mesh="right_outer_knuckle" group="1"/>
        <body name="right_finger" pos="0 -0.035465 0.042039">
	  <geom size="0.008 0.004 0.008" pos="0 0.005 -0.015" quat="0 0 0 1" type="box" group="0" solref="0.01 0.5" friction = "2 0.05 0.0001" conaffinity="1" contype="1" name="finger2_pad_collision"/>
          <site name="ft_frame" pos="0 0 0" size="0.01 0.01 0.01" rgba="1 0 0 1" type="sphere" group="1"/>
          <inertial pos="0 0.016413 0.029258" quat="0.697634 -0.115356 0.115356 0.697634" mass="0.048304"
            diaginertia="1.88038e-05 1.7493e-05 3.56779e-06"/>
          <joint range="0 0.85" axis="1 0 0" frictionloss="1" name="right_finger_joint" solreflimit="0.005 1"/>
          <geom type="mesh" material="black" mesh="right_finger" group="1"/>
        </body>
      </body>
      <body name="right_inner_knuckle" pos="0 -0.02 0.074098">
        <inertial pos="1.866e-06 -0.022047 0.026133" quat="0.66415 0.242702 -0.242721 0.664144" mass="0.023013"
          diaginertia="8.34209e-06 6.0949e-06 2.75601e-06"/>
        <joint range="0 0.85" frictionloss="1" name="right_inner_knuckle_joint" axis="-1 0 0" stiffness="0.05" springref="2.62" damping="0.00125"/>
        <geom type="mesh" material="black" mesh="right_inner_knuckle" group="1"/>
      </body>
      <body name="eef" pos="0 0 0.097" quat="1 0 0 0">
                <site name="grip_site" pos="0 0 0" size="0.01 0.01 0.01" rgba="1 0 0 0.5" type="sphere" group="1"/>
                <site name="ee_x" pos="0.1 0 0" size="0.005 .1"  quat="0.707105  0 0.707108 0 " rgba="1 0 0 0" type="cylinder" group="1"/>
                <site name="ee_y" pos="0 0.1 0" size="0.005 .1" quat="0.707105 0.707108 0 0" rgba="0 1 0 0" type="cylinder" group="1"/>
                <site name="ee_z" pos="0 0 0.1" size="0.005 .1" quat="1 0 0 0" rgba="0 0 1 0" type="cylinder" group="1"/>
                <!-- This site was added for visualization. -->
                <site name="grip_site_cylinder" pos="0 0 0" size="0.005 10" rgba="0 1 0 0.3" type="cylinder" group="1"/>
            </body>
    </body>
  </worldbody>

  <sensor>
    <force name="force_ee" site="ft_frame"/>
    <torque name="torque_ee" site="ft_frame"/>
  </sensor>

  <contact>
    <exclude body1="right_inner_knuckle" body2="right_outer_knuckle"/>
    <exclude body1="right_inner_knuckle" body2="right_finger"/>
    <exclude body1="left_inner_knuckle" body2="left_outer_knuckle"/>
    <exclude body1="left_inner_knuckle" body2="left_finger"/>
    <exclude body1="left_inner_knuckle" body2="xarm_gripper_base_link"/>
    <exclude body1="right_inner_knuckle" body2="xarm_gripper_base_link"/>
    <exclude body1="left_outer_knuckle" body2="xarm_gripper_base_link"/>
    <exclude body1="right_outer_knuckle" body2="xarm_gripper_base_link"/>
  </contact>

  <tendon>
    <fixed name="split">
      <joint joint="right_driver_joint" coef="0.5"/>
      <joint joint="left_driver_joint" coef="0.5"/>
    </fixed>
  </tendon>

  <equality>
    <connect anchor="0 0.015 0.015" body1="right_finger" body2="right_inner_knuckle" solref="0.005 1"/>
    <connect anchor="0 -0.015 0.015" body1="left_finger" body2="left_inner_knuckle" solref="0.005 1"/>
    <joint joint1="left_driver_joint" joint2="right_driver_joint" polycoef="0 1 0 0 0" solref="0.005 1"/>
  </equality>

  <actuator>
    <general biastype="affine" forcerange="-50 50" ctrlrange="0 255" gainprm="0.333" biasprm="0 -100 -10" name="fingers_actuator" tendon="split"/>
  </actuator>
</mujoco>
